Workbook

Sheet Dashboard
B2: LUMINA LIVING · FY2026 FINANCIAL DASHBOARD
B5: REVENUE | E5: GROSS PROFIT | H5: GROSS MARGIN | K5: OPERATING CONTRIBUTION
B6: =Analysis!C4 | E6: =Analysis!C5 | H6: =Analysis!C6 | K6: =Analysis!C7
H25: DEFINITIONS & CONTROLS
H26: Gross margin = Gross profit / Revenue
H27: Operating contribution deducts fulfilment and marketing budget
H28: Scenario assumptions remain separate from actuals
H29: All data is fictional training material
H30: Last refreshed: 12 Aug 2026

Sheet Read_Me
B2: LUMINA LIVING PTE LTD · LAB 07
B5: Activity | C5: Build Financial Analysis and an Excel Dashboard
B6: Decision | C6: Which revenue, margin and cost actions should management prioritise?
B7: Department | C7: Finance and Business Performance
B8: Sponsor | C8: Chief Financial Officer
B9: Fictional data | C9: All names, messages and figures are synthetic training material.
B10: Acceptance | C10: The model has no formula errors, all four KPIs reconcile, scenarios change through named assumptions, three native charts answer management questions and the audit log records independent checks.

Sheet Transactions
A1: Txn_ID | B1: Date | C1: Month | D1: Region | E1: Channel | F1: Product | G1: Category | H1: Units | I1: Unit_Price | J1: Discount_Pct | K1: Revenue | L1: Unit_Cost | M1: Gross_Profit | N1: Fulfilment_Cost
A2: LL-00001 | B2: 46299 | C2: Oct | D2: North | E2: Retail | F2: Focus Monitor Stand | G2: Workspace | H2: 4 | I2: 79 | J2: 0.1 | K2: =H2*I2*(1-J2) | L2: 36 | M2: =K2-(H2*L2) | N2: =H2*6
A3: LL-00002 | B3: 46043 | C3: Jan | D3: East | E3: Online | F3: Halo Floor Lamp | G3: Lighting | H3: 7 | I3: 159 | J3: 0.15 | K3: =H3*I3*(1-J3) | L3: 79 | M3: =K3-(H3*L3) | N3: =H3*11
A4: LL-00003 | B4: 46368 | C4: Dec | D4: East | E4: Retail | F4: Focus Monitor Stand | G4: Workspace | H4: 8 | I4: 79 | J4: 0.05 | K4: =H4*I4*(1-J4) | L4: 36 | M4: =K4-(H4*L4) | N4: =H4*6
A5: LL-00004 | B5: 46300 | C5: Oct | D5: East | E5: Online | F5: Nest Basket | G5: Living | H5: 5 | I5: 55 | J5: 0.1 | K5: =H5*I5*(1-J5) | L5: 24 | M5: =K5-(H5*L5) | N5: =H5*11
A6: LL-00005 | B6: 46147 | C6: May | D6: South | E6: Online | F6: Nest Basket | G6: Living | H6: 6 | I6: 55 | J6: 0 | K6: =H6*I6*(1-J6) | L6: 24 | M6: =K6-(H6*L6) | N6: =H6*11
A7: LL-00006 | B7: 46301 | C7: Oct | D7: South | E7: Marketplace | F7: Luna Throw | G7: Living | H7: 6 | I7: 69 | J7: 0.15 | K7: =H7*I7*(1-J7) | L7: 31 | M7: =K7-(H7*L7) | N7: =H7*15
A8: LL-00007 | B8: 46278 | C8: Sep | D8: East | E8: Marketplace | F8: Aurora Desk Lamp | G8: Lighting | H8: 6 | I8: 89 | J8: 0.05 | K8: =H8*I8*(1-J8) | L8: 42 | M8: =K8-(H8*L8) | N8: =H8*15
A9: LL-00008 | B9: 46375 | C9: Dec | D9: East | E9: Retail | F9: Luna Throw | G9: Living | H9: 7 | I9: 69 | J9: 0.2 | K9: =H9*I9*(1-J9) | L9: 31 | M9: =K9-(H9*L9) | N9: =H9*6
A10: LL-00009 | B10: 46314 | C10: Oct | D10: North | E10: Retail | F10: Halo Floor Lamp | G10: Lighting | H10: 6 | I10: 159 | J10: 0.15 | K10: =H10*I10*(1-J10) | L10: 79 | M10: =K10-(H10*L10) | N10: =H10*6
A11: LL-00010 | B11: 46208 | C11: Jul | D11: North | E11: Marketplace | F11: Nest Basket | G11: Living | H11: 4 | I11: 55 | J11: 0.05 | K11: =H11*I11*(1-J11) | L11: 24 | M11: =K11-(H11*L11) | N11: =H11*15
A12: LL-00011 | B12: 46100 | C12: Mar | D12: South | E12: Online | F12: Nest Basket | G12: Living | H12: 7 | I12: 55 | J12: 0 | K12: =H12*I12*(1-J12) | L12: 24 | M12: =K12-(H12*L12) | N12: =H12*11
A13: LL-00012 | B13: 46097 | C13: Mar | D13: South | E13: Retail | F13: Focus Monitor Stand | G13: Workspace | H13: 6 | I13: 79 | J13: 0.05 | K13: =H13*I13*(1-J13) | L13: 36 | M13: =K13-(H13*L13) | N13: =H13*6
A14: LL-00013 | B14: 46375 | C14: Dec | D14: East | E14: Retail | F14: Aurora Desk Lamp | G14: Lighting | H14: 3 | I14: 89 | J14: 0.15 | K14: =H14*I14*(1-J14) | L14: 42 | M14: =K14-(H14*L14) | N14: =H14*6
A15: LL-00014 | B15: 46279 | C15: Sep | D15: North | E15: Marketplace | F15: Halo Floor Lamp | G15: Lighting | H15: 6 | I15: 159 | J15: 0.05 | K15: =H15*I15*(1-J15) | L15: 79 | M15: =K15-(H15*L15) | N15: =H15*15
A16: LL-00015 | B16: 46294 | C16: Sep | D16: West | E16: Retail | F16: Arc Side Table | G16: Living | H16: 5 | I16: 139 | J16: 0.1 | K16: =H16*I16*(1-J16) | L16: 72 | M16: =K16-(H16*L16) | N16: =H16*6
A17: LL-00016 | B17: 46193 | C17: Jun | D17: North | E17: Retail | F17: Arc Side Table | G17: Living | H17: 1 | I17: 139 | J17: 0 | K17: =H17*I17*(1-J17) | L17: 72 | M17: =K17-(H17*L17) | N17: =H17*6
A18: LL-00017 | B18: 46249 | C18: Aug | D18: North | E18: Retail | F18: Nest Basket | G18: Living | H18: 8 | I18: 55 | J18: 0.05 | K18: =H18*I18*(1-J18) | L18: 24 | M18: =K18-(H18*L18) | N18: =H18*6
A19: LL-00018 | B19: 46323 | C19: Oct | D19: East | E19: Online | F19: Halo Floor Lamp | G19: Lighting | H19: 6 | I19: 159 | J19: 0.1 | K19: =H19*I19*(1-J19) | L19: 79 | M19: =K19-(H19*L19) | N19: =H19*11
A20: LL-00019 | B20: 46243 | C20: Aug | D20: North | E20: Online | F20: Luna Throw | G20: Living | H20: 6 | I20: 69 | J20: 0 | K20: =H20*I20*(1-J20) | L20: 31 | M20: =K20-(H20*L20) | N20: =H20*11
A21: LL-00020 | B21: 46324 | C21: Oct | D21: South | E21: Retail | F21: Arc Side Table | G21: Living | H21: 3 | I21: 139 | J21: 0 | K21: =H21*I21*(1-J21) | L21: 72 | M21: =K21-(H21*L21) | N21: =H21*6
A22: LL-00021 | B22: 46319 | C22: Oct | D22: North | E22: Online | F22: Nest Basket | G22: Living | H22: 4 | I22: 55 | J22: 0.05 | K22: =H22*I22*(1-J22) | L22: 24 | M22: =K22-(H22*L22) | N22: =H22*11
A23: LL-00022 | B23: 46069 | C23: Feb | D23: West | E23: Retail | F23: Aurora Desk Lamp | G23: Lighting | H23: 6 | I23: 89 | J23: 0 | K23: =H23*I23*(1-J23) | L23: 42 | M23: =K23-(H23*L23) | N23: =H23*6
A24: LL-00023 | B24: 46175 | C24: Jun | D24: South | E24: Marketplace | F24: Focus Monitor Stand | G24: Workspace | H24: 1 | I24: 79 | J24: 0 | K24: =H24*I24*(1-J24) | L24: 36 | M24: =K24-(H24*L24) | N24: =H24*15
A25: LL-00024 | B25: 46190 | C25: Jun | D25: North | E25: Online | F25: Focus Monitor Stand | G25: Workspace | H25: 5 | I25: 79 | J25: 0.15 | K25: =H25*I25*(1-J25) | L25: 36 | M25: =K25-(H25*L25) | N25: =H25*11
A26: LL-00025 | B26: 46039 | C26: Jan | D26: North | E26: Online | F26: Nest Basket | G26: Living | H26: 4 | I26: 55 | J26: 0.05 | K26: =H26*I26*(1-J26) | L26: 24 | M26: =K26-(H26*L26) | N26: =H26*11
A27: LL-00026 | B27: 46085 | C27: Mar | D27: East | E27: Retail | F27: Focus Monitor Stand | G27: Workspace | H27: 4 | I27: 79 | J27: 0.05 | K27: =H27*I27*(1-J27) | L27: 36 | M27: =K27-(H27*L27) | N27: =H27*6
A28: LL-00027 | B28: 46047 | C28: Jan | D28: South | E28: Retail | F28: Arc Side Table | G28: Living | H28: 2 | I28: 139 | J28: 0.05 | K28: =H28*I28*(1-J28) | L28: 72 | M28: =K28-(H28*L28) | N28: =H28*6
A29: LL-00028 | B29: 46179 | C29: Jun | D29: East | E29: Retail | F29: Aurora Desk Lamp | G29: Lighting | H29: 4 | I29: 89 | J29: 0.1 | K29: =H29*I29*(1-J29) | L29: 42 | M29: =K29-(H29*L29) | N29: =H29*6
A30: LL-00029 | B30: 46193 | C30: Jun | D30: West | E30: Retail | F30: Arc Side Table | G30: Living | H30: 3 | I30: 139 | J30: 0 | K30: =H30*I30*(1-J30) | L30: 72 | M30: =K30-(H30*L30) | N30: =H30*6
A31: LL-00030 | B31: 46069 | C31: Feb | D31: West | E31: Online | F31: Nest Basket | G31: Living | H31: 3 | I31: 55 | J31: 0.1 | K31: =H31*I31*(1-J31) | L31: 24 | M31: =K31-(H31*L31) | N31: =H31*11
A32: LL-00031 | B32: 46300 | C32: Oct | D32: West | E32: Online | F32: Focus Monitor Stand | G32: Workspace | H32: 1 | I32: 79 | J32: 0.2 | K32: =H32*I32*(1-J32) | L32: 36 | M32: =K32-(H32*L32) | N32: =H32*11
A33: LL-00032 | B33: 46359 | C33: Dec | D33: East | E33: Retail | F33: Aurora Desk Lamp | G33: Lighting | H33: 3 | I33: 89 | J33: 0.05 | K33: =H33*I33*(1-J33) | L33: 42 | M33: =K33-(H33*L33) | N33: =H33*6
A34: LL-00033 | B34: 46272 | C34: Sep | D34: East | E34: Online | F34: Arc Side Table | G34: Living | H34: 2 | I34: 139 | J34: 0.15 | K34: =H34*I34*(1-J34) | L34: 72 | M34: =K34-(H34*L34) | N34: =H34*11
A35: LL-00034 | B35: 46319 | C35: Oct | D35: South | E35: Marketplace | F35: Arc Side Table | G35: Living | H35: 7 | I35: 139 | J35: 0.1 | K35: =H35*I35*(1-J35) | L35: 72 | M35: =K35-(H35*L35) | N35: =H35*15
A36: LL-00035 | B36: 46226 | C36: Jul | D36: East | E36: Online | F36: Focus Monitor Stand | G36: Workspace | H36: 2 | I36: 79 | J36: 0.1 | K36: =H36*I36*(1-J36) | L36: 36 | M36: =K36-(H36*L36) | N36: =H36*11
A37: LL-00036 | B37: 46080 | C37: Feb | D37: North | E37: Online | F37: Nest Basket | G37: Living | H37: 3 | I37: 55 | J37: 0.05 | K37: =H37*I37*(1-J37) | L37: 24 | M37: =K37-(H37*L37) | N37: =H37*11
A38: LL-00037 | B38: 46161 | C38: May | D38: West | E38: Retail | F38: Arc Side Table | G38: Living | H38: 6 | I38: 139 | J38: 0.15 | K38: =H38*I38*(1-J38) | L38: 72 | M38: =K38-(H38*L38) | N38: =H38*6
A39: LL-00038 | B39: 46037 | C39: Jan | D39: South | E39: Online | F39: Luna Throw | G39: Living | H39: 6 | I39: 69 | J39: 0.15 | K39: =H39*I39*(1-J39) | L39: 31 | M39: =K39-(H39*L39) | N39: =H39*11
A40: LL-00039 | B40: 46170 | C40: May | D40: West | E40: Retail | F40: Focus Monitor Stand | G40: Workspace | H40: 5 | I40: 79 | J40: 0 | K40: =H40*I40*(1-J40) | L40: 36 | M40: =K40-(H40*L40) | N40: =H40*6
...

Sheet Budget
A1: Month | B1: Revenue_Budget | C1: Gross_Profit_Budget | D1: Marketing_Budget | E1: Operating_Cost_Budget
A2: Jan | B2: 72000 | C2: 30960 | D2: 11400 | E2: 22400
A3: Feb | B3: 74600 | C3: 32078 | D3: 9000 | E3: 23100
A4: Mar | B4: 77200 | C4: 33196 | D4: 10200 | E4: 21000
A5: Apr | B5: 79800 | C5: 34314 | D5: 11400 | E5: 21700
A6: May | B6: 82400 | C6: 35432 | D6: 9000 | E6: 22400
A7: Jun | B7: 85000 | C7: 36550 | D7: 10200 | E7: 23100
A8: Jul | B8: 87600 | C8: 37668 | D8: 11400 | E8: 21000
A9: Aug | B9: 90200 | C9: 38786 | D9: 9000 | E9: 21700
A10: Sep | B10: 92800 | C10: 39904 | D10: 10200 | E10: 22400
A11: Oct | B11: 95400 | C11: 41022 | D11: 11400 | E11: 23100
A12: Nov | B12: 98000 | C12: 42140 | D12: 9000 | E12: 21000
A13: Dec | B13: 100600 | C13: 43258 | D13: 10200 | E13: 21700

Sheet Assumptions
A1: Assumption | B1: Base value | C1: Definition / control
A2: Unit growth | B2: 0.08 | C2: Applied only to FY2027 scenario
A3: Average discount | B3: 0.09 | C3: Weighted average target
A4: Unit-cost inflation | B4: 0.04 | C4: Supplier planning assumption
A5: Marketing spend change | B5: 0.06 | C5: Versus FY2026 budget

Sheet Analysis
B2: FY2026 ACTUAL VS BUDGET ANALYSIS
B4: Revenue | C4: =SUM(Transactions!K2:K721)
B5: Gross Profit | C5: =SUM(Transactions!M2:M721)
B6: Gross Margin | C6: =IF(C4=0,0,C5/C4)
B7: Operating Contribution | C7: =C5-SUM(Transactions!N2:N721)-SUM(Budget!D2:D13)
B10: Month | C10: Actual Revenue | D10: Budget Revenue | F10: Channel | G10: Revenue | H10: Gross Profit | I10: Contribution
B11: Jan | C11: =SUMIF(Transactions!$C$2:$C$721,B11,Transactions!$K$2:$K$721) | D11: =INDEX(Budget!$B$2:$B$13,MATCH(B11,Budget!$A$2:$A$13,0)) | F11: Retail | G11: =SUMIF(Transactions!$E$2:$E$721,F11,Transactions!$K$2:$K$721) | H11: =SUMIF(Transactions!$E$2:$E$721,F11,Transactions!$M$2:$M$721) | I11: =H11-SUMIF(Transactions!$E$2:$E$721,F11,Transactions!$N$2:$N$721)
B12: Feb | C12: =SUMIF(Transactions!$C$2:$C$721,B12,Transactions!$K$2:$K$721) | D12: =INDEX(Budget!$B$2:$B$13,MATCH(B12,Budget!$A$2:$A$13,0)) | F12: Online | G12: =SUMIF(Transactions!$E$2:$E$721,F12,Transactions!$K$2:$K$721) | H12: =SUMIF(Transactions!$E$2:$E$721,F12,Transactions!$M$2:$M$721) | I12: =H12-SUMIF(Transactions!$E$2:$E$721,F12,Transactions!$N$2:$N$721)
B13: Mar | C13: =SUMIF(Transactions!$C$2:$C$721,B13,Transactions!$K$2:$K$721) | D13: =INDEX(Budget!$B$2:$B$13,MATCH(B13,Budget!$A$2:$A$13,0)) | F13: Marketplace | G13: =SUMIF(Transactions!$E$2:$E$721,F13,Transactions!$K$2:$K$721) | H13: =SUMIF(Transactions!$E$2:$E$721,F13,Transactions!$M$2:$M$721) | I13: =H13-SUMIF(Transactions!$E$2:$E$721,F13,Transactions!$N$2:$N$721)
B14: Apr | C14: =SUMIF(Transactions!$C$2:$C$721,B14,Transactions!$K$2:$K$721) | D14: =INDEX(Budget!$B$2:$B$13,MATCH(B14,Budget!$A$2:$A$13,0))
B15: May | C15: =SUMIF(Transactions!$C$2:$C$721,B15,Transactions!$K$2:$K$721) | D15: =INDEX(Budget!$B$2:$B$13,MATCH(B15,Budget!$A$2:$A$13,0))
B16: Jun | C16: =SUMIF(Transactions!$C$2:$C$721,B16,Transactions!$K$2:$K$721) | D16: =INDEX(Budget!$B$2:$B$13,MATCH(B16,Budget!$A$2:$A$13,0))
B17: Jul | C17: =SUMIF(Transactions!$C$2:$C$721,B17,Transactions!$K$2:$K$721) | D17: =INDEX(Budget!$B$2:$B$13,MATCH(B17,Budget!$A$2:$A$13,0))
B18: Aug | C18: =SUMIF(Transactions!$C$2:$C$721,B18,Transactions!$K$2:$K$721) | D18: =INDEX(Budget!$B$2:$B$13,MATCH(B18,Budget!$A$2:$A$13,0))
B19: Sep | C19: =SUMIF(Transactions!$C$2:$C$721,B19,Transactions!$K$2:$K$721) | D19: =INDEX(Budget!$B$2:$B$13,MATCH(B19,Budget!$A$2:$A$13,0))
B20: Oct | C20: =SUMIF(Transactions!$C$2:$C$721,B20,Transactions!$K$2:$K$721) | D20: =INDEX(Budget!$B$2:$B$13,MATCH(B20,Budget!$A$2:$A$13,0))
B21: Nov | C21: =SUMIF(Transactions!$C$2:$C$721,B21,Transactions!$K$2:$K$721) | D21: =INDEX(Budget!$B$2:$B$13,MATCH(B21,Budget!$A$2:$A$13,0))
B22: Dec | C22: =SUMIF(Transactions!$C$2:$C$721,B22,Transactions!$K$2:$K$721) | D22: =INDEX(Budget!$B$2:$B$13,MATCH(B22,Budget!$A$2:$A$13,0))

Sheet Source_Register
A1: ID | B1: Source | C1: Owner | D1: Approved use | E1: Last reviewed | F1: Status
A2: S01 | B2: FY2026 transaction ledger | C2: Finance and Business Performance | D2: Which revenue, margin and cost actions should management prioritise? | E2: 46246 | F2: Approved for training
A3: S02 | B3: Monthly budget | C3: Finance and Business Performance | D3: Which revenue, margin and cost actions should management prioritise? | E3: 46246 | F3: Approved for training
A4: S03 | B4: Product cost table | C4: Finance and Business Performance | D4: Which revenue, margin and cost actions should management prioritise? | E4: 46246 | F4: Approved for training
A5: S04 | B5: Scenario assumptions | C5: Finance and Business Performance | D5: Which revenue, margin and cost actions should management prioritise? | E5: 46246 | F5: Approved for training

Sheet Audit_Log
A1: Date | B1: Check | C1: Evidence / change | D1: Owner | E1: Reviewer | F1: Status
A2: 46246 | B2: Starter created | C2: Fictional training workbook generated | D2: Courseware team | F2: Open
